Workbook

Sheet Assumptions
A1: ASSUMPTIONS TAB
A3: REVENUE ASSUMPTIONS | C3: 2026E | D3: 2027E | E3: 2028E | G3: Source/Justification
A4: Automotive Sales Growth % | C4: -0.05 | D4: 0.05 | E4: 0.08 | G4: Deliveries fell 9% in 2025, recovery via Cybercab 2027
A5: Regulatory Credits ($M) | C5: 1800 | D5: 1600 | E5: 1400 | G5: Declining as competitors electrify
A6: Automotive Leasing Growth % | C6: 0.08 | D6: 0.1 | E6: 0.12 | G6: Growing FSD subscription model
A7: Energy Generation & Storage Growth % | C7: 0.27 | D7: 0.3 | E7: 0.28 | G7: Record deployments, Megapack 3 launching 2026
A8: Services & Other Growth % | C8: 0.19 | D8: 0.2 | E8: 0.18 | G8: FSD subscriptions + Robotaxi expansion
A9: Total revenue growth used | C9: -0.05 | D9: 0.05 | E9: 0.08
A10: MARGIN ASSUMPTIONS | C10: 2026E | D10: 2027E | E10: 2028E | G10: Source/Justification
A11: Gross Margin % | C11: 0.185 | D11: 0.195 | E11: 0.205 | G11: Gradual recovery via cost efficiency
A12: R&D as % of Revenue | C12: 0.07 | D12: 0.068 | E12: 0.065 | G12: AI investment stabilising after 2025 peak
A13: SG&A as % of Revenue | C13: 0.062 | D13: 0.06 | E13: 0.058 | G13: Operational leverage as revenue grows
A14: Effective Tax Rate % | C14: 0.255 | D14: 0.255 | E14: 0.255 | G14: Normalised rate removing 2023 one-off
A15: BELOW THE LINE ASSUMPTIONS | C15: 2026E | D15: 2027E | E15: 2028E | G15: Source/Justification
A16: Interest Income % of Cash Balance | C16: 0.038 | D16: 0.038 | E16: 0.038 | G16: Based on current US interest rates
A17: Interest Expense ($M) | C17: 338 | D17: 320 | E17: 300 | G17: Gradual debt reduction
A18: Other Non-Operating Income ($M) | C18: 0 | D18: 0 | E18: 0 | G18: Conservative - no one-off items assumed
A19: KEY METRICS ASSUMPTIONS | C19: 2026E | D19: 2027E | E19: 2028E | G19: Source/Justification
A20: D&A Growth % | C20: 0.05 | D20: 0.05 | E20: 0.05 | G20: Based on PP&E expansion trend
A21: Capex as % of Revenue | C21: 0.09 | D21: 0.085 | E21: 0.082 | G21: Post-peak investment cycle
A22: Shares Outstanding Basic (M) | C22: 3241 | D22: 3257 | E22: 3273 | G22: 0.5% annual dilution from SBC
A23: Shares Outstanding Diluted (M) | C23: 3546 | D23: 3564 | E23: 3582 | G23: 0.5% annual dilution from SBC
A24: CURRENT ASSETS ASSUMPTIONS | C24: 2026E | D24: 2027E | E24: 2028E | G24: Justification
A25: Accounts Receivable % of Revenue | C25: 0.049 | D25: 0.049 | E25: 0.049 | G25: Based on 2025 actual revenue
A26: Inventory % of Revenue | C26: 0.131 | D26: 0.13 | E26: 0.128 | G26: Slight efficiency improvement
A27: Prepaid Expenses % of Revenue | C27: 0.075 | D27: 0.073 | E27: 0.07 | G27: Gradual normalisation
A28: Other Receivables % of Revenue | C28: 0.001 | D28: 0.001 | E28: 0.001 | G28: Keep flat based on 2025
A29: Restricted Cash ($M) | C29: 389 | D29: 389 | E29: 389 | G29: Keep flat - regulatory requirement
A30: NON-CURRENT ASSETS ASSUMPTIONS | C30: 2026E | D30: 2027E | E30: 2028E | G30: Justification
A31: Long-Term Deferred Tax Assets ($M) | C31: 6925 | D31: 6925 | E31: 6925 | G31: Keep flat - no new one-off items
A32: Other Long-Term Assets % of Revenue | C32: 0.049 | D32: 0.049 | E32: 0.049 | G32: Based on 2025 actual revenue
A33: Long-Term Accounts Receivable % of Revenue | C33: 0.015 | D33: 0.015 | E33: 0.014 | G33: Gradual decline
A34: CURRENT LIABILITIES ASSUMPTIONS | C34: 2026E | D34: 2027E | E34: 2028E | G34: Justification
A35: Accounts Payable % of Revenue | C35: 0.141 | D35: 0.14 | E35: 0.138 | G35: Stable supplier payment terms
A36: Accrued Expenses % of Revenue | C36: 0.047 | D36: 0.047 | E36: 0.047 | G36: Based on 2025 actual
A37: Current Unearned Revenue % of Revenue | C37: 0.036 | D37: 0.037 | E37: 0.038 | G37: Growing FSD subscriptions
A38: Current Income Taxes Payable % of Revenue | C38: 0.017 | D38: 0.017 | E38: 0.017 | G38: Based on 2025 actual
A39: Other Current Liabilities % of Revenue | C39: 0.066 | D39: 0.066 | E39: 0.065 | G39: Based on 2025 actual
A40: Current Portion of Leases ($M) | C40: 1025 | D40: 1025 | E40: 1025 | G40: Keep flat
A41: NON-CURRENT LIABILITIES ASSUMPTIONS | C41: 2026E | D41: 2027E | E41: 2028E | G41: Justification
...

Sheet Income Statement
F1: Tesla, Inc
C3: 2021 | D3: 2022 | E3: 2023 | F3: 2024 | G3: 2025 | H3: 2026 E | I3: 2027E | J3: 2028 E
B4: REVENUES
B5: Revenue | C5: 53823 | D5: 81462 | E5: 96773 | F5: 97690 | G5: 94827 | H5: =G5*(1+Assumptions!C4) -> 90085.65 | I5: =H5*(1+Assumptions!D4) -> 94589.932 | J5: =I5*(1+Assumptions!E4) -> 102157.13
B7: COST OF REVENUES
B8: Cost of Revenue | C8: -40217 | D8: -60609 | E8: -79113 | F8: -80240 | G8: -77733 | H8: =-H5*(1-H11) -> -73419.805 | I8: =-I5*(1-I11) -> -76144.896 | J8: =-J5*(1-J11) -> -81214.916
B10: Gross Profit | C10: =C5+C8 -> 13606 | D10: =D5+D8 -> 20853 | E10: =E5+E8 -> 17660 | F10: =F5+F8 -> 17450 | G10: =G5+G8 -> 17094 | H10: =H5+H8 -> 16665.845 | I10: =I5+I8 -> 18445.037 | J10: =J5+J8 -> 20942.211
B11: Gross Margin % | C11: =C10/C5 -> 0.25279156 | D11: =D10/D5 -> 0.25598439 | E11: =E10/E5 -> 0.18248892 | F11: =F10/F5 -> 0.17862627 | G11: =G10/G5 -> 0.18026511 | H11: =Assumptions!C11 -> 0.185 | I11: =Assumptions!D11 -> 0.195 | J11: =Assumptions!E11 -> 0.205
B13: OPERATING EXPENSES
B14: Selling General & Admin | C14: -4517 | D14: -3946 | E14: -4800 | F14: -5150 | G14: -5834 | H14: =-H5*Assumptions!C13 -> -5585.3103 | I14: =-I5*Assumptions!D13 -> -5675.3959 | J14: =-J5*Assumptions!E13 -> -5925.1134
B15: Research & Development | C15: -2593 | D15: -3075 | E15: -3969 | F15: -4540 | G15: -6411 | H15: =-H5*Assumptions!C12 -> -6305.9955 | I15: =-I5*Assumptions!D12 -> -6432.1154 | J15: =-J5*Assumptions!E12 -> -6640.2133
B16: Other Operating Expenses | C16: 27 | D16: -140 | E16: 0 | F16: -101 | G16: -494 | H16: 0 | I16: 0 | J16: 0
B17: Total Operating Expenses | C17: =SUM(C14:C16) -> -7083 | D17: =SUM(D14:D16) -> -7161 | E17: =SUM(E14:E16) -> -8769 | F17: =SUM(F14:F16) -> -9791 | G17: =SUM(G14:G16) -> -12739 | H17: =SUM(H14:H16) -> -11891.306 | I17: =SUM(I14:I16) -> -12107.511 | J17: =SUM(J14:J16) -> -12565.327
B19: OPERATING INCOME (EBIT) | C19: =C10+C17 -> 6523 | D19: =D10+D17 -> 13692 | E19: =E10+E17 -> 8891 | F19: =F10+F17 -> 7659 | G19: =G10+G17 -> 4355 | H19: =H10+H17 -> 4774.5395 | I19: =I10+I17 -> 6337.5255 | J19: =J10+J17 -> 8376.8844
B20: Operating Margin % | C20: =C19/C5 -> 0.12119354 | D20: =D19/D5 -> 0.16807837 | E20: =E19/E5 -> 0.0918748 | F20: =F19/F5 -> 0.078401065 | G20: =G19/G5 -> 0.045925738 | H20: =H19/H5 -> 0.053 | I20: =I19/I5 -> 0.067 | J20: =J19/J5 -> 0.082
B22: BELOW THE LINE
B23: Interest Expense | C23: -371 | D23: -191 | E23: -156 | F23: -350 | G23: -338 | H23: =-Assumptions!C17 -> -338 | I23: =-Assumptions!D17 -> -320 | J23: =-Assumptions!E17 -> -300
B24: Interest & Investment Income | C24: 56 | D24: 297 | E24: 1066 | F24: 1569 | G24: 1680 | H24: ='Balance Sheet'!G7*Assumptions!C16 -> 1674.242 | I24: ='Balance Sheet'!H7*Assumptions!D16 -> 1849.0462 | J24: ='Balance Sheet'!I7*Assumptions!E16 -> 2252.8008
B25: Currency Exchange Gain/(Loss) | C25: 97 | D25: -89 | E25: 122 | F25: 57 | G25: 407 | H25: 0 | I25: 0 | J25: 0
B26: Other Non-Operating Income | C26: 38 | D26: 46 | E26: 50 | F26: 638 | G26: -826 | H26: 0 | I26: 0 | J26: 0
B27: Merger Charges | D27: -36 | F27: -583 | H27: 0 | I27: 0 | J27: 0
B28: Pretax Income | C28: =C19+C23+C24+C25+C26 -> 6343 | D28: =D19+D23+D24+D25+D26+D27 -> 13719 | E28: =E19+E23+E24+E25+E26+E27 -> 9973 | F28: =F19+F23+F24+F25+F26+F27 -> 8990 | G28: =G19+G23+G24+G25+G26+G27 -> 5278 | H28: =H19+H23+H24+H25+H26 -> 6110.7815 | I28: =I19+I23+I24+I25+I26 -> 7866.5716 | J28: =J19+J23+J24+J25+J26 -> 10329.685
B29: Income Tax Expense | C29: -699 | D29: -1132 | E29: 5001 | F29: -1837 | G29: -1423 | H29: =-H28*Assumptions!C14 -> -1558.2493 | I29: =-I28*Assumptions!D14 -> -2005.9758 | J29: =-J28*Assumptions!E14 -> -2634.0697
B30: Minority Interest | C30: -125 | D30: -31 | E30: 23 | F30: -62 | G30: -61 | H30: =G30*(1-5%) -> -57.95 | I30: =H30*(1-5%) -> -55.0525 | J30: =I30*(1-5%) -> -52.299875
B32: NET INCOME | C32: =C28+C29+C30 -> 5519 | D32: =D28+D29+D30 -> 12556 | E32: =E28+E29+E30 -> 14997 | F32: =F28+F29+F30 -> 7091 | G32: =G28+G29+G30 -> 3794 | H32: =H28+H29+H30 -> 4494.5822 | I32: =I28+I29+I30 -> 5805.5434 | J32: =J28+J29+J30 -> 7643.3156
B33: Preferred Dividends | C33: 5 | D33: 27 | E33: 2 | F33: 39 | G33: 0 | H33: =G33 -> 0 | I33: =H33 -> 0 | J33: =I33 -> 0
B34: NET INCOME TO COMMON | C34: =C32+C33 -> 5524 | D34: =D32+D33 -> 12583 | E34: =E32+E33 -> 14999 | F34: =F32+F33 -> 7130 | G34: =G32+G33 -> 3794 | H34: =H32+H33 -> 4494.5822 | I34: =I32+I33 -> 5805.5434 | J34: =J32+J33 -> 7643.3156
B36: Shares Outstanding Basic (M) | C36: 2959 | D36: 3130 | E36: 3174 | F36: 3197 | G36: 3225 | H36: =Assumptions!C22 -> 3241 | I36: =Assumptions!D22 -> 3257 | J36: =Assumptions!E22 -> 3273
B37: Shares Outstanding Diluted (M) | C37: 3386 | D37: 3475 | E37: 3485 | F37: 3498 | G37: 3528 | H37: =Assumptions!C23 -> 3546 | I37: =Assumptions!D23 -> 3564 | J37: =Assumptions!E23 -> 3582
B39: EPS Basic | C39: =C34/C36 -> 1.8668469 | D39: =D34/D36 -> 4.0201278 | E39: =E34/E36 -> 4.7255829 | F39: =F34/F36 -> 2.2302158 | G39: =G34/G36 -> 1.1764341 | H39: =H34/H36 -> 1.3867887 | I39: =I34/I36 -> 1.7824818 | J39: =J34/J36 -> 2.3352629
B40: EPS Diluted | C40: =C34/C37 -> 1.6314235 | D40: =D34/D37 -> 3.6210072 | E40: =E34/E37 -> 4.3038737 | F40: =F34/F37 -> 2.0383076 | G40: =G34/G37 -> 1.0753968 | H40: =H34/H37 -> 1.2675077 | I40: =I34/I37 -> 1.6289403 | J40: =J34/J37 -> 2.1338123
B41: FCF | C41: =C56+C57 -> 4983 | D41: =D56+D57 -> 7561 | E41: =E56+E57 -> 4357 | F41: =F56+F57 -> 3581 | G41: =G56+G57 -> 6220 | H41: =H56+H57 -> 3486.2496 | I41: =I56+I57 -> 9415.2825 | J41: =J56+J57 -> 12226.786
B42: GROWTH & MARGINS
B43: Revenue Growth % | D43: =(D5-C5)/C5 -> 0.51351653 | E43: =(E5-D5)/D5 -> 0.18795267 | F43: =(F5-E5)/E5 -> 0.0094757835 | G43: =(G5-F5)/F5 -> -0.029306992 | H43: =(H5-G5)/G5 -> -0.05 | I43: =(I5-H5)/H5 -> 0.05 | J43: =(J5-I5)/I5 -> 0.08
B44: Gross Margin % | C44: =C11 -> 0.25279156 | D44: =D11 -> 0.25598439 | E44: =E11 -> 0.18248892 | F44: =F11 -> 0.17862627 | G44: =G11 -> 0.18026511 | H44: =H11 -> 0.185 | I44: =I11 -> 0.195 | J44: =J11 -> 0.205
B45: Operating Margin % | C45: =C20 -> 0.12119354 | D45: =D20 -> 0.16807837 | E45: =E20 -> 0.0918748 | F45: =F20 -> 0.078401065 | G45: =G20 -> 0.045925738 | H45: =H20 -> 0.053 | I45: =I20 -> 0.067 | J45: =J20 -> 0.082
B46: Net Margin % | C46: =C32/C5 -> 0.10253981 | D46: =D32/D5 -> 0.15413322 | E46: =E32/E5 -> 0.15497091 | F46: =F32/F5 -> 0.072586754 | G46: =G32/G5 -> 0.040009702 | H46: =H32/H5 -> 0.049892321 | I46: =I32/I5 -> 0.061375912 | J46: =J32/J5 -> 0.07481921
B47: Free Cash Flow Margin % | C47: =C41/C5 -> 0.092581239 | D47: =D41/D5 -> 0.092816282 | E47: =E41/E5 -> 0.045022889 | F47: =F41/F5 -> 0.036656771 | G47: =G41/G5 -> 0.065593133 | H47: =H41/H5 -> 0.038699278 | I47: =I41/I5 -> 0.099537892 | J47: =J41/J5 -> 0.11968608
B48: KEY METRICS
B49: EBITDA | C49: =C19+C51 -> 9434 | D49: =D19+D51 -> 17235 | E49: =E19+E51 -> 13558 | F49: =F19+F51 -> 13027 | G49: =G19+G51 -> 10503 | H49: =H19+H51 -> 11229.939 | I49: =I19+I51 -> 13115.695 | J49: =J19+J51 -> 15493.963
...

Sheet Balance Sheet
C3: 2021A | D3: 2022A | E3: 2023A | F3: 2024A | G3: 2025A | H3: 2026E | I3: 2027E | J3: 2028E
B5: ASSETS
B6: CURRENT ASSETS
B7: Cash & Marketable Securities | C7: 17707 | D7: 22185 | E7: 29094 | F7: 36563 | G7: 44059 | H7: =G7+'Cash Flow'!H29 -> 48659.11 | I7: =H7+'Cash Flow'!I29 -> 59284.231 | J7: =I7+'Cash Flow'!J29 -> 72732.953
B8: Accounts Receivable | C8: 1986 | D8: 3116 | E8: 3319 | F8: 4255 | G8: 4598 | H8: =(H60/365)*'Income Statement'!H5 -> 4195.77 | I8: =(I60/365)*'Income Statement'!I5 -> 4405.5585 | J8: =(J60/365)*'Income Statement'!J5 -> 4478.1206
B9: Other Receivables | C9: 0 | D9: 0 | E9: 378 | F9: 315 | G9: 108 | H9: 108 | I9: 108 | J9: 108
B10: Total Receivables | C10: =C8+C9 -> 1986 | D10: =D8+D9 -> 3116 | E10: =E8+E9 -> 3697 | F10: =F8+F9 -> 4570 | G10: =G8+G9 -> 4706 | H10: =H8+H9 -> 4303.77 | I10: =I8+I9 -> 4513.5585 | J10: =J8+J9 -> 4586.1206
B11: Inventory | C11: 5757 | D11: 12839 | E11: 13626 | F11: 12017 | G11: 12392 | H11: =(Assumptions!C54/365)*(-'Income Statement'!H8) -> 11465.559 | I11: =(Assumptions!D54/365)*(-'Income Statement'!I8) -> 11473.888 | J11: =(Assumptions!E54/365)*(-'Income Statement'!J8) -> 11792.851
B12: Prepaid Expenses | C12: 1305 | D12: 2483 | E12: 2656 | F12: 4716 | G12: 7096 | H12: ='Income Statement'!H5*Assumptions!C27 -> 6756.4237 | I12: ='Income Statement'!I5*Assumptions!D27 -> 6905.0651 | J12: ='Income Statement'!J5*Assumptions!E27 -> 7150.9989
B13: Restricted Cash | C13: 345 | D13: 294 | E13: 543 | F13: 494 | G13: 389 | H13: 389 | I13: 389 | J13: 389
B14: Total Current Assets | C14: =C7+C10+C11+C12+C13 -> 27100 | D14: =D7+D10+D11+D12+D13 -> 40917 | E14: =E7+E10+E11+E12+E13 -> 49616 | F14: =F7+F10+F11+F12+F13 -> 58360 | G14: =G7+G10+G11+G12+G13 -> 68642 | H14: =H7+H10+H11+H12+H13 -> 71573.862 | I14: =I7+I10+I11+I12+I13 -> 82565.743 | J14: =J7+J10+J11+J12+J13 -> 96651.924
B16: NON-CURRENT ASSETS
B17: Property Plant & Equipment | C17: 31176 | D17: 36635 | E17: 45123 | F17: 51501 | G17: 56186 | H17: =G17-'Cash Flow'!H16-'Cash Flow'!H5 -> 57838.308 | I17: =H17-'Cash Flow'!I16-'Cash Flow'!I5 -> 59100.283 | J17: =I17-'Cash Flow'!J16-'Cash Flow'!J5 -> 60360.089
B18: Goodwill | C18: 200 | D18: 194 | E18: 253 | F18: 0 | G18: 0 | H18: 0 | I18: 0 | J18: 0
B19: Other Intangible Assets | C19: 257 | D19: 215 | E19: 178 | F19: 0 | G19: 0 | H19: 0 | I19: 0 | J19: 0
B20: Long-Term Accounts Receivable | C20: 303 | D20: 1626 | E20: 2125 | F20: 1767 | G20: 1395 | H20: ='Income Statement'!H5*Assumptions!C33 -> 1351.2847 | I20: ='Income Statement'!I5*Assumptions!D33 -> 1418.849 | J20: ='Income Statement'!J5*Assumptions!E33 -> 1430.1998
B21: Long-Term Deferred Tax Assets | C21: 0 | D21: 328 | E21: 6733 | F21: 6524 | G21: 6925 | H21: 6925 | I21: 6925 | J21: 6925
B22: Other Long-Term Assets | C22: 3095 | D22: 2423 | E22: 2590 | F22: 3918 | G22: 4658 | H22: ='Income Statement'!H5*Assumptions!C32 -> 4414.1969 | I22: ='Income Statement'!I5*Assumptions!D32 -> 4634.9067 | J22: ='Income Statement'!J5*Assumptions!E32 -> 5005.6992
B23: Total Assets | C23: =SUM(C17:C22)+C14 -> 62131 | D23: =SUM(D17:D22)+D14 -> 82338 | E23: =SUM(E17:E22)+E14 -> 106618 | F23: =SUM(F17:F22)+F14 -> 122070 | G23: =SUM(G17:G22)+G14 -> 137806 | H23: =SUM(H17:H22)+H14 -> 142102.65 | I23: =SUM(I17:I22)+I14 -> 154644.78 | J23: =SUM(J17:J22)+J14 -> 170372.91
B25: LIABILITIES
B26: CURRENT LIABILITIES
B27: Accounts Payable | C27: 10025 | D27: 15255 | E27: 14431 | F27: 12474 | G27: 13371 | H27: =(Assumptions!C53/365)*(-'Income Statement'!H8) -> 12471.309 | I27: =(Assumptions!D53/365)*(-'Income Statement'!I8) -> 13142.818 | J27: =(Assumptions!E53/365)*(-'Income Statement'!J8) -> 14240.424
B28: Accrued Expenses | C28: 2951 | D28: 3773 | E28: 4046 | F28: 3785 | G28: 4484 | H28: ='Income Statement'!H5*Assumptions!C36 -> 4234.0255 | I28: ='Income Statement'!I5*Assumptions!D36 -> 4445.7268 | J28: ='Income Statement'!J5*Assumptions!E36 -> 4801.385
B29: Current Portion of Long-Term Debt | C29: 1088 | D29: 1016 | E29: 1975 | F29: 2343 | G29: 1569 | H29: =Assumptions!C43 -> 1569 | I29: =Assumptions!D43 -> 1500 | J29: =Assumptions!E43 -> 1400
B30: Current Portion of Leases | C30: 869 | D30: 971 | E30: 1070 | F30: 920 | G30: 1025 | H30: =G30*102% -> 1045.5 | I30: =H30*102% -> 1066.41 | J30: =I30*102% -> 1087.7382
B31: Current Income Taxes Payable | C31: 1122 | D31: 1235 | E31: 1204 | F31: 1367 | G31: 1594 | H31: ='Income Statement'!H5*Assumptions!C38 -> 1531.4561 | I31: ='Income Statement'!I5*Assumptions!D38 -> 1608.0289 | J31: ='Income Statement'!J5*Assumptions!E38 -> 1736.6712
B32: Current Unearned Revenue | C32: 1447 | D32: 1747 | E32: 2864 | F32: 3168 | G32: 3424 | H32: ='Income Statement'!H5*Assumptions!C37 -> 3243.0834 | I32: ='Income Statement'!I5*Assumptions!D37 -> 3499.8275 | J32: ='Income Statement'!J5*Assumptions!E37 -> 3881.9708
B33: Other Current Liabilities | C33: 2203 | D33: 2712 | E33: 3158 | F33: 4764 | G33: 6247 | H33: ='Income Statement'!H5*Assumptions!C39 -> 5945.6529 | I33: ='Income Statement'!I5*Assumptions!D39 -> 6242.9355 | J33: ='Income Statement'!J5*Assumptions!E39 -> 6640.2133
B34: Total Current Liabilities | C34: =SUM(C27:C33) -> 19705 | D34: =SUM(D27:D33) -> 26709 | E34: =SUM(E27:E33) -> 28748 | F34: =SUM(F27:F33) -> 28821 | G34: =SUM(G27:G33) -> 31714 | H34: =SUM(H27:H33) -> 30040.027 | I34: =SUM(I27:I33) -> 31505.746 | J34: =SUM(J27:J33) -> 33788.402
B36: NON-CURRENT LIABILITIES
B37: Long-Term Debt | C37: 4254 | D37: 1029 | E37: 2682 | F37: 5535 | G37: 6584 | H37: =Assumptions!C42 -> 6500 | I37: =Assumptions!D42 -> 6200 | J37: =Assumptions!E42 -> 5900
B38: Long-Term Leases | C38: 2662 | D38: 2732 | E38: 3846 | F38: 4825 | G38: 5541 | H38: =Assumptions!C44 -> 5707 | I38: =Assumptions!D44 -> 5878 | J38: =Assumptions!E44 -> 6054
B39: Long-Term Unearned Revenue | C39: 2052 | D39: 2804 | E39: 3251 | F39: 3317 | G39: 3631 | H39: ='Income Statement'!H5*Assumptions!C45 -> 3423.2547 | I39: ='Income Statement'!I5*Assumptions!D45 -> 3689.0074 | J39: ='Income Statement'!J5*Assumptions!E45 -> 4086.2851
B40: Long-Term Deferred Tax Liabilities | C40: 24 | D40: 0 | E40: 0 | F40: 0 | G40: 0 | H40: 0 | I40: 0 | J40: 0
B41: Other Long-Term Liabilities | C41: 1851 | D41: 3166 | E41: 4482 | F41: 5892 | G41: 7471 | H41: =Assumptions!C46 -> 7845 | I41: =Assumptions!D46 -> 8237 | J41: =Assumptions!E46 -> 8649
B42: Total Liabilities | C42: =SUM(C37:C41)+C34 -> 30548 | D42: =SUM(D37:D41)+D34 -> 36440 | E42: =SUM(E37:E41)+E34 -> 43009 | F42: =SUM(F37:F41)+F34 -> 48390 | G42: =SUM(G37:G41)+G34 -> 54941 | H42: =SUM(H37:H41)+H34 -> 53515.282 | I42: =SUM(I37:I41)+I34 -> 55509.754 | J42: =SUM(J37:J41)+J34 -> 58477.687
B44: EQUITY
B45: Common Stock | C45: 3 | D45: 3 | E45: 3 | F45: 3 | G45: 3 | H45: 3 | I45: 3 | J45: 3
B46: Additional Paid-In Capital | C46: =C23-C42-C45-C47-C48-C50 -> 29803 | D46: =D23-D42-D45-D47-D48-D50 -> 32177 | E46: =E23-E42-E45-E47-E48-E50 -> 34892 | F46: =F23-F42-F45-F47-F48-F50 -> 38371 | G46: =G23-G42-G45-G47-G48-G50 -> 42770 | H46: =H23-H42-H45-H47-H48-H50 -> 44034.188 | I46: =I23-I42-I45-I47-I48-I50 -> 48810.882 | J46: =J23-J42-J45-J47-J48-J50 -> 53960.614
B47: Retained Earnings | C47: 329 | D47: 12885 | E47: 27882 | F47: 35209 | G47: 39003 | H47: =G47+'Cash Flow'!H4 -> 43497.582 | I47: =H47+'Cash Flow'!I4 -> 49303.126 | J47: =I47+'Cash Flow'!J4 -> 56946.441
...

Sheet Cash Flow
B3: Metric | C3: FY 2021 | D3: FY 2022 | E3: FY 2023 | F3: FY 2024 | G3: FY 2025 | H3: 2026 E | I3: 2027 E | J3: 2028 E
B4: Net Income | C4: 5519 | D4: 12556 | E4: 14997 | F4: 7091 | G4: 3794 | H4: ='Income Statement'!H32 -> 4494.5822 | I4: ='Income Statement'!I32 -> 5805.5434 | J4: ='Income Statement'!J32 -> 7643.3156
B5: Depreciation & Amortization | C5: 2911 | D5: 3543 | E5: 4667 | F5: 5368 | G5: 6148 | H5: ='Income Statement'!H51 -> 6455.4 | I5: ='Income Statement'!I51 -> 6778.17 | J5: ='Income Statement'!J51 -> 7117.0785
B6: Asset Writedown & Restructuring Costs | C6: 0 | D6: 204 | E6: 0 | F6: 0 | G6: 0 | H6: 0 | I6: 0 | J6: 0
B7: Stock-Based Compensation | C7: 2121 | D7: 1560 | E7: 1812 | F7: 1999 | G7: 2825 | H7: =Assumptions!C49 -> 2500 | I7: =Assumptions!D49 -> 2600 | J7: =Assumptions!E49 -> 2700
B8: Other Operating Activities | C8: 279 | D8: 573 | E8: -5972 | F8: 384 | G8: 1338 | H8: 765 | I8: 765 | J8: 765
B9: Change in Accounts Receivable | C9: -130 | D9: -1124 | E9: -586 | F9: -1083 | G9: -261 | H9: ='Balance Sheet'!H8-'Balance Sheet'!G8 -> -402.23 | I9: ='Balance Sheet'!I8-'Balance Sheet'!H8 -> 209.7885 | J9: ='Balance Sheet'!J8-'Balance Sheet'!I8 -> 72.56214
B10: Change in Inventory | C10: -1709 | D10: -6465 | E10: -1195 | F10: 937 | G10: -630 | H10: ='Balance Sheet'!H11-'Balance Sheet'!G11 -> -926.44145 | I10: ='Balance Sheet'!I11-'Balance Sheet'!H11 -> 8.3298375 | J10: ='Balance Sheet'!J11-'Balance Sheet'!I11 -> 318.96244
B11: Change in Accounts Payable | C11: 5367 | D11: 8029 | E11: 2605 | F11: 3588 | G11: 4376 | H11: ='Balance Sheet'!H27-'Balance Sheet'!G27 -> -899.6907 | I11: ='Balance Sheet'!I27-'Balance Sheet'!H27 -> 671.50831 | J11: ='Balance Sheet'!J27-'Balance Sheet'!I27 -> 1097.606
B12: Change in Unearned Revenue | C12: 793 | D12: 1131 | E12: 1532 | F12: 502 | G12: 363 | H12: ='Balance Sheet'!H32-'Balance Sheet'!G32 -> -180.9166 | I12: ='Balance Sheet'!I32-'Balance Sheet'!H32 -> 256.7441 | J12: ='Balance Sheet'!J32-'Balance Sheet'!I32 -> 382.14333
B13: Change in Other Net Operating Assets | C13: -3654 | D13: -5283 | E13: -4604 | F13: -3863 | G13: -3206 | H13: =-('Balance Sheet'!H12-'Balance Sheet'!G12)+('Balance Sheet'!H28-'Balance Sheet'!G28)+('Balance Sheet'!H33-'Balance Sheet'!G33) -> -211.7453 | I13: =-('Balance Sheet'!I12-'Balance Sheet'!H12)+('Balance Sheet'!I28-'Balance Sheet'!H28)+('Balance Sheet'!I33-'Balance Sheet'!H33) -> 360.3426 | J13: =-('Balance Sheet'!J12-'Balance Sheet'!I12)+('Balance Sheet'!J28-'Balance Sheet'!I28)+('Balance Sheet'!J33-'Balance Sheet'!I33) -> 507.00204
B14: Operating Cash Flow | C14: =SUM('Cash Flow'!C4:C13) -> 11497 | D14: =SUM('Cash Flow'!D4:D13) -> 14724 | E14: =SUM('Cash Flow'!E4:E13) -> 13256 | F14: =SUM('Cash Flow'!F4:F13) -> 14923 | G14: =SUM('Cash Flow'!G4:G13) -> 14747 | H14: =SUM('Cash Flow'!H4:H13) -> 11593.958 | I14: =SUM('Cash Flow'!I4:I13) -> 17455.427 | J14: =SUM('Cash Flow'!J4:J13) -> 20603.67
B15: Operating Cash Flow Growth (%) | C15: 0.9345 | D15: =(D14-C14)/C14 -> 0.28068192 | E15: =(E14-D14)/D14 -> -0.099701168 | F15: =(F14-E14)/E14 -> 0.12575438 | G15: =(G14-F14)/F14 -> -0.011793875 | H15: =(H14-G14)/G14 -> -0.21380904 | I15: =(I14-H14)/H14 -> 0.50556234 | J15: =(J14-I14)/I14 -> 0.180359
B16: Capital Expenditures | C16: -6514 | D16: -7163 | E16: -8899 | F16: -11342 | G16: -8527 | H16: ='Income Statement'!H57 -> -8107.7085 | I16: ='Income Statement'!I57 -> -8040.1443 | J16: ='Income Statement'!J57 -> -8376.8844
B17: Cash Acquisitions | C17: 0 | D17: 0 | E17: -64 | F17: 0 | G17: 0 | H17: 0 | I17: 0 | J17: 0
B18: Sale (Purchase) of Intangibles | C18: 0 | D18: -9 | E18: 0 | F18: 0 | G18: 0 | H18: 0 | I18: 0 | J18: 0
B19: Investment in Securities | C19: -132 | D19: -5813 | E19: -6621 | F19: -7445 | G19: -6951 | H19: 0 | I19: 0 | J19: 0
B20: Other Investing Activities | C20: -1222 | D20: 1012 | E20: 0 | F20: 0 | G20: 0 | H20: 0 | I20: 0 | J20: 0
B21: Investing Cash Flow | C21: =SUM(C16:C20) -> -7868 | D21: =SUM(D16:D20) -> -11973 | E21: =SUM(E16:E20) -> -15584 | F21: =SUM(F16:F20) -> -18787 | G21: =SUM(G16:G20) -> -15478 | H21: =SUM(H16:H20) -> -8107.7085 | I21: =SUM(I16:I20) -> -8040.1443 | J21: =SUM(J16:J20) -> -8376.8844
B22: Long-Term Debt Issued | C22: 8883 | D22: 0 | E22: 3931 | F22: 5744 | G22: 5586 | H22: 0 | I22: 0 | J22: 0
B23: Long-Term Debt Repaid | C23: -14615 | D23: -3866 | E23: -1815 | F23: -2881 | G23: -5650 | H23: -84 | I23: 0 | J23: 0
B24: Net Debt Issued (Repaid) | C24: -5732 | D24: -3866 | E24: 2116 | F24: 2863 | G24: -64 | H24: =-(H22-H23) -> -84 | I24: =I22-I23 -> 0 | J24: =J22-J23 -> 0
B25: Issuance of Common Stock | C25: 707 | D25: 541 | E25: 700 | F25: 1241 | G25: 1186 | H25: =G25*101% -> 1197.86 | I25: =H25*101% -> 1209.8386 | J25: =I25*101% -> 1221.937
B26: Other Financing Activities | C26: -178 | D26: -202 | E26: -227 | F26: -251 | G26: 17 | H26: 0 | I26: 0 | J26: 0
B27: Financing Cash Flow | C27: =C24+C25+C26 -> -5203 | D27: =D24+D25+D26 -> -3527 | E27: =E24+E25+E26 -> 2589 | F27: =F24+F25+F26 -> 3853 | G27: =G24+G25+G26 -> 1139 | H27: =H24+H25+H26 -> 1113.86 | I27: =I24+I25+I26 -> 1209.8386 | J27: =J24+J25+J26 -> 1221.937
B28: Foreign Exchange Rate Adjustments | C28: -183 | D28: -444 | E28: 4 | F28: -141 | G28: 171 | H28: 0 | I28: 0 | J28: 0
B29: Net Cash Flow | C29: =C14+C21+C27+C28 -> -1757 | D29: =D14+D21+D27+D28 -> -1220 | E29: =E14+E21+E27+E28 -> 265 | F29: =F14+F21+F27+F28 -> -152 | G29: =G14+G21+G27+G28 -> 579 | H29: =H14+H21+H27+H28 -> 4600.1096 | I29: =I14+I21+I27+I28 -> 10625.121 | J29: =J14+J21+J27+J28 -> 13448.723
B30: Free Cash Flow | C30: 4983 | D30: 7561 | E30: 4357 | F30: 3581 | G30: 6220 | H30: =H14+H16 -> 3486.2496 | I30: =I14+I16 -> 9415.2825 | J30: =J14+J16 -> 12226.786
B31: Free Cash Flow Growth (%) | C31: 0.8381 | D31: 0.5174 | E31: -0.4238 | F31: -0.1781 | G31: 0.7369 | H31: =(H30-G30)/G30 -> -0.43950971 | I31: =(I30-H30)/H30 -> 1.7006908 | J31: =(J30-I30)/I30 -> 0.2986106
B32: Free Cash Flow Margin (%) | C32: =C30/'Income Statement'!C5 -> 0.092581239 | D32: =D30/'Income Statement'!D5 -> 0.092816282 | E32: =E30/'Income Statement'!E5 -> 0.045022889 | F32: =F30/'Income Statement'!F5 -> 0.036656771 | G32: =G30/'Income Statement'!G5 -> 0.065593133 | H32: =H30/'Income Statement'!H5 -> 0.038699278 | I32: =I30/'Income Statement'!I5 -> 0.099537892 | J32: =J30/'Income Statement'!J5 -> 0.11968608
B33: Free Cash Flow Per Share | C33: ='Cash Flow'!C30/'Income Statement'!C37 -> 1.471648 | D33: ='Cash Flow'!D30/'Income Statement'!D37 -> 2.1758273 | E33: ='Cash Flow'!E30/'Income Statement'!E37 -> 1.2502152 | F33: ='Cash Flow'!F30/'Income Statement'!F37 -> 1.0237278 | G33: ='Cash Flow'!G30/'Income Statement'!G37 -> 1.7630385 | H33: ='Cash Flow'!H30/'Income Statement'!H37 -> 0.98314992 | I33: ='Cash Flow'!I30/'Income Statement'!I37 -> 2.641774 | J33: ='Cash Flow'!J30/'Income Statement'!J37 -> 3.4133963
B34: Cash Interest Paid | C34: 266 | D34: 152 | E34: 126 | F34: 277 | G34: 292 | H34: ='Balance Sheet'!H55*4% -> 592.86 | I34: ='Balance Sheet'!I55*4% -> 585.7764 | J34: ='Balance Sheet'!J55*4% -> 577.66953
B35: Cash Income Tax Paid | C35: 561 | D35: 1203 | E35: 1120 | F35: 1330 | G35: 1232 | H35: ='Income Statement'!H19*Assumptions!C14 -> 1217.5076 | I35: ='Income Statement'!I19*Assumptions!D14 -> 1616.069 | J35: ='Income Statement'!J19*Assumptions!E14 -> 2136.1055
B36: Unlevered Free Cash Flow | C36: 6453 | D36: 4124 | E36: 2328 | F36: -608.13 | G36: 3944 | H36: ='Income Statement'!H19*(1-0.25)+'Income Statement'!H51+'Income Statement'!H57-H37 -> 1926.6858 | I36: ='Income Statement'!I19*(1-0.25)+'Income Statement'!I51+'Income Statement'!I57-I37 -> 4413.0052 | J36: ='Income Statement'!J19*(1-0.25)+'Income Statement'!J51+'Income Statement'!J57-J37 -> 6466.7403
B37: Change in Working Capital | C37: 667 | D37: -3712 | E37: -2248 | F37: 81 | G37: 642 | H37: =H9+H10-H11-H38-H12 -> 1.9103 | I37: =I9+I10-I11-I38-I12 -> -921.83535 | J37: =J9+J10-J11-J38-J12 -> -1443.8829
B38: Change in Accrued Expenses | D38: ='Balance Sheet'!D28-'Balance Sheet'!C28 -> 822 | E38: ='Balance Sheet'!E28-'Balance Sheet'!D28 -> 273 | F38: ='Balance Sheet'!F28-'Balance Sheet'!E28 -> -261 | G38: ='Balance Sheet'!G28-'Balance Sheet'!F28 -> 699 | H38: ='Balance Sheet'!H28-'Balance Sheet'!G28 -> -249.97445 | I38: ='Balance Sheet'!I28-'Balance Sheet'!H28 -> 211.70128 | J38: ='Balance Sheet'!J28-'Balance Sheet'!I28 -> 355.65815

Sheet DCF
B2: RF | C2: 0.044 | F2: 1 | G2: 2 | H2: 3 | K2: E | L2: E | M2: E | P2: Bear | Q2: Base | R2: Bull
B3: BETA | C3: 1.8 | F3: 2021 | G3: 2022 | H3: 2023 | I3: 2024 | J3: 2025 | K3: 2026 | L3: 2027 | M3: 2028 | O3: Assumption
B4: Risk Premium | C4: 0.045 | E4: EBIT | F4: ='Income Statement'!C19 -> 6523 | G4: ='Income Statement'!D19 -> 13692 | H4: ='Income Statement'!E19 -> 8891 | I4: ='Income Statement'!F19 -> 7659 | J4: ='Income Statement'!G19 -> 4355 | K4: ='Income Statement'!H19 -> 4774.5395 | L4: ='Income Statement'!I19 -> 6337.5255 | M4: ='Income Statement'!J19 -> 8376.8844 | O4: Revenue Growth | P4: =Assumptions!C9 -> -0.05 | Q4: =Assumptions!D9 -> 0.05 | R4: =Assumptions!E9 -> 0.08
B5: kd | C5: =-'Income Statement'!G23/'Balance Sheet'!G55 -> 0.022963517 | E5: Tax | F5: =F4*$C$7 -> 1663.365 | G5: =G4*$C$7 -> 3491.46 | H5: =H4*$C$7 -> 2267.205 | I5: =I4*$C$7 -> 1953.045 | J5: =J4*$C$7 -> 1110.525 | K5: =K4*$C$7 -> 1217.5076 | L5: =L4*$C$7 -> 1616.069 | M5: =M4*$C$7 -> 2136.1055 | O5: EBITDA | P5: 0.17 | Q5: 0.185 | R5: 0.21
B6: ke | C6: =C2+C3*C4 -> 0.125 | E6: EBIT (1-T) | F6: =F4-F5 -> 4859.635 | G6: =G4-G5 -> 10200.54 | H6: =H4-H5 -> 6623.795 | I6: =I4-I5 -> 5705.955 | J6: =J4-J5 -> 3244.475 | K6: =K4-K5 -> 3557.0319 | L6: =L4-L5 -> 4721.4565 | M6: =M4-M5 -> 6240.7789 | O6: WACC | P6: 0.14 | Q6: 0.124 | R6: 0.1
B7: Tax | C7: 0.255 | E7: Depreciation | F7: ='Cash Flow'!C5 -> 2911 | G7: ='Cash Flow'!D5 -> 3543 | H7: ='Cash Flow'!E5 -> 4667 | I7: ='Cash Flow'!F5 -> 5368 | J7: ='Cash Flow'!G5 -> 6148 | K7: ='Cash Flow'!H5 -> 6455.4 | L7: ='Cash Flow'!I5 -> 6778.17 | M7: ='Cash Flow'!J5 -> 7117.0785 | O7: TERMINAL GROWTH | P7: 0.015 | Q7: 0.025 | R7: 0.035
B8: kd(1-t) | C8: =C5*(1-C7) -> 0.01710782 | E8: Capex | F8: ='Cash Flow'!C16 -> -6514 | G8: ='Cash Flow'!D16 -> -7163 | H8: ='Cash Flow'!E16 -> -8899 | I8: ='Cash Flow'!F16 -> -11342 | J8: ='Cash Flow'!G16 -> -8527 | K8: ='Cash Flow'!H16 -> -8107.7085 | L8: ='Cash Flow'!I16 -> -8040.1443 | M8: ='Cash Flow'!J16 -> -8376.8844
B9: Total Market Cap | C9: 1550000 | E9: Working Capital | F9: =('Balance Sheet'!C14-'Balance Sheet'!C7)-('Balance Sheet'!C34-'Balance Sheet'!C29-'Balance Sheet'!C30) -> -8355 | G9: =('Balance Sheet'!D14-'Balance Sheet'!D7)-('Balance Sheet'!D34-'Balance Sheet'!D29-'Balance Sheet'!D30) -> -5990 | H9: =('Balance Sheet'!E14-'Balance Sheet'!E7)-('Balance Sheet'!E34-'Balance Sheet'!E29-'Balance Sheet'!E30) -> -5181 | I9: =('Balance Sheet'!F14-'Balance Sheet'!F7)-('Balance Sheet'!F34-'Balance Sheet'!F29-'Balance Sheet'!F30) -> -3761 | J9: =('Balance Sheet'!G14-'Balance Sheet'!G7)-('Balance Sheet'!G34-'Balance Sheet'!G29-'Balance Sheet'!G30) -> -4537 | K9: =('Balance Sheet'!H14-'Balance Sheet'!H7)-('Balance Sheet'!H34-'Balance Sheet'!H29-'Balance Sheet'!H30) -> -4510.7749 | L9: =('Balance Sheet'!I14-'Balance Sheet'!I7)-('Balance Sheet'!I34-'Balance Sheet'!I29-'Balance Sheet'!I30) -> -5657.8244 | M9: =('Balance Sheet'!J14-'Balance Sheet'!J7)-('Balance Sheet'!J34-'Balance Sheet'!J29-'Balance Sheet'!J30) -> -7381.6935
B10: Total debt | C10: 13800 | E10: Change in Working Capital | G10: =-(G9-F9) -> -2365 | H10: =-(H9-G9) -> -809 | I10: =-(I9-H9) -> -1420 | J10: =-(J9-I9) -> 776 | K10: =-(K9-J9) -> -26.2251 | L10: =-(L9-K9) -> 1147.0495 | M10: =-(M9-L9) -> 1723.8691
B11: WE | C11: =C9/(C9+C10) -> 0.99117534 | E11: FCFF | G11: =G6+G7+G8+G10 -> 4215.54 | H11: =H6+H7+H8+H10 -> 1582.795 | I11: =I6+I7+I8+I10 -> -1688.045 | J11: =J6+J7+J8+J10 -> 1641.475 | K11: =K6+K7+K8+K10 -> 1878.4983 | L11: =L6+L7+L8+L10 -> 4606.5317 | M11: =M6+M7+M8+M10 -> 6704.8421
B12: WD | C12: =C10/(C10+C9) -> 0.0088246579
B13: Wacc | C13: =C6*C11+C8*C12 -> 0.12404789 | E13: Discount Factor | F13: =1/(1+$C$13)^F2 -> 0.88964181 | G13: =1/(1+$C$13)^G2 -> 0.79146255 | H13: =1/(1+$C$13)^H2 -> 0.70411818
B15: G | C15: 0.03 | F15: 2026 | G15: 2027 | H15: 2028 | L15: Wacc
E16: Present Value of the Firm | F16: =K11*F13 -> 1671.1906 | G16: =L11*G13 -> 3645.8973 | H16: =M11*H13 -> 4721.0012 | I16: =SUM(F16:H16) -> 10038.089 | L16: 0.09 | M16: 0.1 | N16: 0.11 | O16: 0.12 | P16: 0.13 | Q16: 0.14 | R16: 0.15
K17: 0.02 | L17: =(($K$11/(1+L$16)^1) +($L$11/(1+L$16)^2) +($M$11/(1+L$16)^3) +($M$11*(1+$K17)/(L$16-$K17))/(1+L$16)^3 +'Balance Sheet'!$G$7 -'Balance Sheet'!$G$55 -'Balance Sheet'!$G$50) /'Income Statement'!$G$37 -> 32.548651 | M17: =(($K$11/(1+M$16)^1) +($L$11/(1+M$16)^2) +($M$11/(1+M$16)^3) +($M$11*(1+$K17)/(M$16-$K17))/(1+M$16)^3 +'Balance Sheet'!$G$7 -'Balance Sheet'!$G$55 -'Balance Sheet'!$G$50) /'Income Statement'!$G$37 -> 29.30603 | N17: =(($K$11/(1+N$16)^1) +($L$11/(1+N$16)^2) +($M$11/(1+N$16)^3) +($M$11*(1+$K17)/(N$16-$K17))/(1+N$16)^3 +'Balance Sheet'!$G$7 -'Balance Sheet'!$G$55 -'Balance Sheet'!$G$50) /'Income Statement'!$G$37 -> 26.787855 | O17: =(($K$11/(1+O$16)^1) +($L$11/(1+O$16)^2) +($M$11/(1+O$16)^3) +($M$11*(1+$K17)/(O$16-$K17))/(1+O$16)^3 +'Balance Sheet'!$G$7 -'Balance Sheet'!$G$55 -'Balance Sheet'!$G$50) /'Income Statement'!$G$37 -> 24.776678 | P17: =(($K$11/(1+P$16)^1) +($L$11/(1+P$16)^2) +($M$11/(1+P$16)^3) +($M$11*(1+$K17)/(P$16-$K17))/(1+P$16)^3 +'Balance Sheet'!$G$7 -'Balance Sheet'!$G$55 -'Balance Sheet'!$G$50) /'Income Statement'!$G$37 -> 23.134128 | Q17: =(($K$11/(1+Q$16)^1) +($L$11/(1+Q$16)^2) +($M$11/(1+Q$16)^3) +($M$11*(1+$K17)/(Q$16-$K17))/(1+Q$16)^3 +'Balance Sheet'!$G$7 -'Balance Sheet'!$G$55 -'Balance Sheet'!$G$50) /'Income Statement'!$G$37 -> 21.767961 | R17: =(($K$11/(1+R$16)^1) +($L$11/(1+R$16)^2) +($M$11/(1+R$16)^3) +($M$11*(1+$K17)/(R$16-$K17))/(1+R$16)^3 +'Balance Sheet'!$G$7 -'Balance Sheet'!$G$55 -'Balance Sheet'!$G$50) /'Income Statement'!$G$37 -> 20.61432
E18: Terminal Value | F18: =M11*(1+C15)/(C13-C15) -> 73430.541 | J18: g | K18: 0.025 | L18: =(($K$11/(1+L$16)^1) +($L$11/(1+L$16)^2) +($M$11/(1+L$16)^3) +($M$11*(1+$K18)/(L$16-$K18))/(1+L$16)^3 +'Balance Sheet'!$G$7 -'Balance Sheet'!$G$55 -'Balance Sheet'!$G$50) /'Income Statement'!$G$37 -> 34.306435 | M18: =(($K$11/(1+M$16)^1) +($L$11/(1+M$16)^2) +($M$11/(1+M$16)^3) +($M$11*(1+$K18)/(M$16-$K18))/(1+M$16)^3 +'Balance Sheet'!$G$7 -'Balance Sheet'!$G$55 -'Balance Sheet'!$G$50) /'Income Statement'!$G$37 -> 30.614891 | N18: =(($K$11/(1+N$16)^1) +($L$11/(1+N$16)^2) +($M$11/(1+N$16)^3) +($M$11*(1+$K18)/(N$16-$K18))/(1+N$16)^3 +'Balance Sheet'!$G$7 -'Balance Sheet'!$G$55 -'Balance Sheet'!$G$50) /'Income Statement'!$G$37 -> 27.795999 | O18: =(($K$11/(1+O$16)^1) +($L$11/(1+O$16)^2) +($M$11/(1+O$16)^3) +($M$11*(1+$K18)/(O$16-$K18))/(1+O$16)^3 +'Balance Sheet'!$G$7 -'Balance Sheet'!$G$55 -'Balance Sheet'!$G$50) /'Income Statement'!$G$37 -> 25.574067 | P18: =(($K$11/(1+P$16)^1) +($L$11/(1+P$16)^2) +($M$11/(1+P$16)^3) +($M$11*(1+$K18)/(P$16-$K18))/(1+P$16)^3 +'Balance Sheet'!$G$7 -'Balance Sheet'!$G$55 -'Balance Sheet'!$G$50) /'Income Statement'!$G$37 -> 23.778432 | Q18: =(($K$11/(1+Q$16)^1) +($L$11/(1+Q$16)^2) +($M$11/(1+Q$16)^3) +($M$11*(1+$K18)/(Q$16-$K18))/(1+Q$16)^3 +'Balance Sheet'!$G$7 -'Balance Sheet'!$G$55 -'Balance Sheet'!$G$50) /'Income Statement'!$G$37 -> 22.297797 | R18: =(($K$11/(1+R$16)^1) +($L$11/(1+R$16)^2) +($M$11/(1+R$16)^3) +($M$11*(1+$K18)/(R$16-$K18))/(1+R$16)^3 +'Balance Sheet'!$G$7 -'Balance Sheet'!$G$55 -'Balance Sheet'!$G$50) /'Income Statement'!$G$37 -> 21.056482
K19: 0.03 | L19: =(($K$11/(1+L$16)^1) +($L$11/(1+L$16)^2) +($M$11/(1+L$16)^3) +($M$11*(1+$K19)/(L$16-$K19))/(1+L$16)^3 +'Balance Sheet'!$G$7 -'Balance Sheet'!$G$55 -'Balance Sheet'!$G$50) /'Income Statement'!$G$37 -> 36.357183 | M19: =(($K$11/(1+M$16)^1) +($L$11/(1+M$16)^2) +($M$11/(1+M$16)^3) +($M$11*(1+$K19)/(M$16-$K19))/(1+M$16)^3 +'Balance Sheet'!$G$7 -'Balance Sheet'!$G$55 -'Balance Sheet'!$G$50) /'Income Statement'!$G$37 -> 32.110731 | N19: =(($K$11/(1+N$16)^1) +($L$11/(1+N$16)^2) +($M$11/(1+N$16)^3) +($M$11*(1+$K19)/(N$16-$K19))/(1+N$16)^3 +'Balance Sheet'!$G$7 -'Balance Sheet'!$G$55 -'Balance Sheet'!$G$50) /'Income Statement'!$G$37 -> 28.930161 | O19: =(($K$11/(1+O$16)^1) +($L$11/(1+O$16)^2) +($M$11/(1+O$16)^3) +($M$11*(1+$K19)/(O$16-$K19))/(1+O$16)^3 +'Balance Sheet'!$G$7 -'Balance Sheet'!$G$55 -'Balance Sheet'!$G$50) /'Income Statement'!$G$37 -> 26.460055 | P19: =(($K$11/(1+P$16)^1) +($L$11/(1+P$16)^2) +($M$11/(1+P$16)^3) +($M$11*(1+$K19)/(P$16-$K19))/(1+P$16)^3 +'Balance Sheet'!$G$7 -'Balance Sheet'!$G$55 -'Balance Sheet'!$G$50) /'Income Statement'!$G$37 -> 24.487167 | Q19: =(($K$11/(1+Q$16)^1) +($L$11/(1+Q$16)^2) +($M$11/(1+Q$16)^3) +($M$11*(1+$K19)/(Q$16-$K19))/(1+Q$16)^3 +'Balance Sheet'!$G$7 -'Balance Sheet'!$G$55 -'Balance Sheet'!$G$50) /'Income Statement'!$G$37 -> 22.8758 | R19: =(($K$11/(1+R$16)^1) +($L$11/(1+R$16)^2) +($M$11/(1+R$16)^3) +($M$11*(1+$K19)/(R$16-$K19))/(1+R$16)^3 +'Balance Sheet'!$G$7 -'Balance Sheet'!$G$55 -'Balance Sheet'!$G$50) /'Income Statement'!$G$37 -> 21.53549
E20: Present Value of Terminal Value | F20: =F18*H13 -> 51703.779 | K20: 0.035 | L20: =(($K$11/(1+L$16)^1) +($L$11/(1+L$16)^2) +($M$11/(1+L$16)^3) +($M$11*(1+$K20)/(L$16-$K20))/(1+L$16)^3 +'Balance Sheet'!$G$7 -'Balance Sheet'!$G$55 -'Balance Sheet'!$G$50) /'Income Statement'!$G$37 -> 38.780795 | M20: =(($K$11/(1+M$16)^1) +($L$11/(1+M$16)^2) +($M$11/(1+M$16)^3) +($M$11*(1+$K20)/(M$16-$K20))/(1+M$16)^3 +'Balance Sheet'!$G$7 -'Balance Sheet'!$G$55 -'Balance Sheet'!$G$50) /'Income Statement'!$G$37 -> 33.836701 | N20: =(($K$11/(1+N$16)^1) +($L$11/(1+N$16)^2) +($M$11/(1+N$16)^3) +($M$11*(1+$K20)/(N$16-$K20))/(1+N$16)^3 +'Balance Sheet'!$G$7 -'Balance Sheet'!$G$55 -'Balance Sheet'!$G$50) /'Income Statement'!$G$37 -> 30.215545 | O20: =(($K$11/(1+O$16)^1) +($L$11/(1+O$16)^2) +($M$11/(1+O$16)^3) +($M$11*(1+$K20)/(O$16-$K20))/(1+O$16)^3 +'Balance Sheet'!$G$7 -'Balance Sheet'!$G$55 -'Balance Sheet'!$G$50) /'Income Statement'!$G$37 -> 27.450277 | P20: =(($K$11/(1+P$16)^1) +($L$11/(1+P$16)^2) +($M$11/(1+P$16)^3) +($M$11*(1+$K20)/(P$16-$K20))/(1+P$16)^3 +'Balance Sheet'!$G$7 -'Balance Sheet'!$G$55 -'Balance Sheet'!$G$50) /'Income Statement'!$G$37 -> 25.270506 | Q20: =(($K$11/(1+Q$16)^1) +($L$11/(1+Q$16)^2) +($M$11/(1+Q$16)^3) +($M$11*(1+$K20)/(Q$16-$K20))/(1+Q$16)^3 +'Balance Sheet'!$G$7 -'Balance Sheet'!$G$55 -'Balance Sheet'!$G$50) /'Income Statement'!$G$37 -> 23.50885 | R20: =(($K$11/(1+R$16)^1) +($L$11/(1+R$16)^2) +($M$11/(1+R$16)^3) +($M$11*(1+$K20)/(R$16-$K20))/(1+R$16)^3 +'Balance Sheet'!$G$7 -'Balance Sheet'!$G$55 -'Balance Sheet'!$G$50) /'Income Statement'!$G$37 -> 22.056151
K21: 0.04 | L21: =(($K$11/(1+L$16)^1) +($L$11/(1+L$16)^2) +($M$11/(1+L$16)^3) +($M$11*(1+$K21)/(L$16-$K21))/(1+L$16)^3 +'Balance Sheet'!$G$7 -'Balance Sheet'!$G$55 -'Balance Sheet'!$G$50) /'Income Statement'!$G$37 -> 41.689129 | M21: =(($K$11/(1+M$16)^1) +($L$11/(1+M$16)^2) +($M$11/(1+M$16)^3) +($M$11*(1+$K21)/(M$16-$K21))/(1+M$16)^3 +'Balance Sheet'!$G$7 -'Balance Sheet'!$G$55 -'Balance Sheet'!$G$50) /'Income Statement'!$G$37 -> 35.850333 | N21: =(($K$11/(1+N$16)^1) +($L$11/(1+N$16)^2) +($M$11/(1+N$16)^3) +($M$11*(1+$K21)/(N$16-$K21))/(1+N$16)^3 +'Balance Sheet'!$G$7 -'Balance Sheet'!$G$55 -'Balance Sheet'!$G$50) /'Income Statement'!$G$37 -> 31.684555 | O21: =(($K$11/(1+O$16)^1) +($L$11/(1+O$16)^2) +($M$11/(1+O$16)^3) +($M$11*(1+$K21)/(O$16-$K21))/(1+O$16)^3 +'Balance Sheet'!$G$7 -'Balance Sheet'!$G$55 -'Balance Sheet'!$G$50) /'Income Statement'!$G$37 -> 28.564277 | P21: =(($K$11/(1+P$16)^1) +($L$11/(1+P$16)^2) +($M$11/(1+P$16)^3) +($M$11*(1+$K21)/(P$16-$K21))/(1+P$16)^3 +'Balance Sheet'!$G$7 -'Balance Sheet'!$G$55 -'Balance Sheet'!$G$50) /'Income Statement'!$G$37 -> 26.140882 | Q21: =(($K$11/(1+Q$16)^1) +($L$11/(1+Q$16)^2) +($M$11/(1+Q$16)^3) +($M$11*(1+$K21)/(Q$16-$K21))/(1+Q$16)^3 +'Balance Sheet'!$G$7 -'Balance Sheet'!$G$55 -'Balance Sheet'!$G$50) /'Income Statement'!$G$37 -> 24.205205 | R21: =(($K$11/(1+R$16)^1) +($L$11/(1+R$16)^2) +($M$11/(1+R$16)^3) +($M$11*(1+$K21)/(R$16-$K21))/(1+R$16)^3 +'Balance Sheet'!$G$7 -'Balance Sheet'!$G$55 -'Balance Sheet'!$G$50) /'Income Statement'!$G$37 -> 22.624145
E22: Enterprise Value | F22: =F20+I16 -> 61741.868
E24: Equity Value | F24: =F22+'Balance Sheet'!G7-'Balance Sheet'!G55-'Balance Sheet'!G50 -> 90353.868
E25: Shares Outstanding | F25: ='Income Statement'!G37 -> 3528
E26: Share price | F26: =F24/F25 -> 25.610507

Sheet Visual Chart
C3: 2021 | D3: 2022 | E3: 2023 | F3: 2024 | G3: 2025 | H3: 2026 E | I3: 2027E | J3: 2028 E
B5: Revenue | C5: 53823 | D5: 81462 | E5: 96773 | F5: 97690 | G5: 94827 | H5: =G5*(1+Assumptions!C4) -> 90085.65 | I5: =H5*(1+Assumptions!D4) -> 94589.932 | J5: =I5*(1+Assumptions!E4) -> 102157.13
B6: EBITDA | C6: ='Income Statement'!C49 -> 9434 | D6: ='Income Statement'!D49 -> 17235 | E6: ='Income Statement'!E49 -> 13558 | F6: ='Income Statement'!F49 -> 13027 | G6: ='Income Statement'!G49 -> 10503 | H6: ='Income Statement'!H49 -> 11229.939 | I6: ='Income Statement'!I49 -> 13115.695 | J6: ='Income Statement'!J49 -> 15493.963
